Workbook

Sheet LK_Kabkot
A1: PENGUKURAN KINERJA TRIWULAN I TAHUN 2026
A3: Satuan Kerja : | E3: BPS Kabupaten/Kota Tapin
A4: Nilai SAKIP 2026:
A5: Predikat SAKIP 2026: | E5: =IF(E4>90, "AA/Sangat Memuaskan", IF(E4>80, "A/Memuaskan", IF(E4>70, "BB/Sangat Baik", IF(E4>60, "B/Baik", IF(E4>50, "CC/Cukup (Memadai)", IF(E4>30, "C/Kurang", "D/Sangat Kurang")))))) -> D/Sangat Kurang
A7: Tujuan/Sasaran/Indikator Kinerja | H7: Jenis (IKU atau Proksi) | I7: Jenis (Triwulanan atau Tahunan) | J7: Jenis (% atau Non %) | K7: Target | L7: Satuan | M7: Alokasi Target (Kumulatif) | Q7: Realisasi (Kumulatif) | U7: Capaian Kinerja | AC7: Analisis Pencapaian Kinerja di Triwulan Berjalan
U8: Terhadap Target Triwulanan | Y8: Terhadap Target Setahun | AC8: Kendala yang dihadapi pada Triwulan Berjalan | AD8: Solusi yang sudah dilakukan pada Triwulan Berjalan | AE8: Rencana Tindak lanjut | AF8: PIC Tindak Lanjut | AG8: Batas Waktu Tindak lanjut | AH8: Link Bukti Dukung Kinerja | AI8: Link Bukti Dukung Tindak Lanjut Triwulan Sebelumnya
M9: TW I | N9: TW II | O9: TW III | P9: TW IV | Q9: TW I | R9: TW II | S9: TW III | T9: TW IV | U9: TW I | V9: TW II | W9: TW III | X9: TW IV | Y9: TW I | Z9: TW II | AA9: TW III | AB9: TW IV
A10: T1: Mewujudkan Perumusan Kebijakan dan Pengambilan Keputusan Berbasis Data Statistik Berkualitas dan Insight yang Relevan
B11: 1.1.1 | C11: Terwujudnya Penyediaan Data dan Insight Statistik Kependudukan dan Ketenagakerjaan yang Berkualitas
D12: 1.1.1.1 | E12: Persentase Publikasi/Laporan Statistik Kependudukan dan Ketenagakerjaan yang Berkualitas
E13: X: Jumlah Publikasi/Laporan Statistik Kependudukan dan Ketenagakerjaan yang berkualitas
E14: Y: Jumlah seluruh Publikasi/Laporan Statistik Kependudukan dan Ketenagakerjaan yang dihasilkan
B16: 1.1.3 | C16: Terwujudnya Penyediaan Data dan Insight Statistik Kesejahteraan Rakyat yang Berkualitas
D17: 1.1.3.1 | E17: Terwujudnya Penyediaan Data dan Insight Statistik Kesejahteraan Rakyat yang Berkualitas
E18: X: Jumlah Publikasi/Laporan Statistik Kesejahteraan Rakyat yang berkualitas
E19: Y: Jumlah seluruh Publikasi/Laporan Statistik Kesejahteraan Rakyat yang dihasilkan
B21: 1.1.5 | C21: Terwujudnya penyediaan Data dan Insight Statistik Ketahanan Sosial yang Berkualitas
D22: 1.1.5.1 | E22: Persentase Publikasi/Laporan Statistik Ketahanan Sosial yang Berkualitas
E23: X: Jumlah Publikasi/Laporan Statistik Ketahanan Sosial yang berkualitas
E24: Y: Jumlah seluruh Publikasi/Laporan Statistik Ketahanan Sosial yang dihasilkan
B26: 1.2.1 | C26: Terwujudnya Penyediaan Data dan Insight Statistik Sumber Daya Hayati yang Berkualitas
D27: 1.2.1.1 | E27: Persentase Publikasi/Laporan Statistik Sumber Daya Hayati yang Berkualitas
E28: X: Jumlah Publikasi/Laporan Statistik Sumber Daya Hayati yang berkualitas
E29: Y: Jumlah seluruh Publikasi/Laporan Statistik Sumber Daya Hayati yang dihasilkan
B31: 1.2.2 | C31: Terwujudnya Penyediaan Data dan Insight Statistik Sumber Daya Mineral dan Konstruksi yang Berkualitas
D32: 1.2.2.1 | E32: Persentase publikasi/laporan Statistik Sumber Daya Mineral dan Konstruksi yang Berkualitas
E33: X: Jumlah Publikasi/Laporan Statistik Sumber Daya Mineral dan Konstruksi yang berkualitas
E34: Y: Jumlah seluruh Publikasi/Laporan Statistik Sumber Daya Mineral dan Konstruksi yang dihasilkan yang dihasilkan
B36: 1.2.3 | C36: Terwujudnya penyediaan Data dan Insight Statistik Industri yang Berkualitas
D37: 1.2.3.1 | E37: Persentase publikasi/laporan Statistik Industri yang Berkualitas
E38: X: Jumlah Publikasi/Laporan Statistik Industri yang berkualitas
E39: Y: Jumlah seluruh Publikasi/Laporan Statistik Industri yang dihasilkan
B41: 1.3.1 | C41: Terwujudnya Penyediaan Data dan Insight Statistik Distribusi yang Berkualitas
D42: 1.3.1.1 | E42: Persentase Publikasi/Laporan Statistik Distribusi yang Berkualitas
E43: X: Jumlah Publikasi/Laporan Statistik Distribusi yang berkualitas
E44: Y: Jumlah seluruh Publikasi/Laporan Statistik Distribusi yang dihasilkan
B46: 1.3.3 | C46: Terwujudnya Penyediaan Data dan Insight Statistik Harga yang Berkualitas
D47: 1.3.3.1 | E47: Persentase Publikasi/laporan Statistik Harga yang Berkualitas
E48: X: Jumlah Publikasi/Laporan Statistik Harga yang berkualitas
E49: Y: Jumlah seluruh Publikasi/Laporan Statistik Harga yang dihasilkan
...

Sheet FRA_input
A2: Indikator Kinerja/Uraian | E2: Jenis | F2: Target | G2: Satuan | H2: Alokasi Target | L2: Realisasi | P2: Capaian Kinerja | X2: Analisis Pencapaian Kinerja di Triwulan Berjalan
P3: Terhadap Target Triwulanan | T3: Terhadap Target Setahun | X3: Kendala | Y3: Solusi | Z3: RTL | AA3: PIC TL | AB3: Batas Waktu TL | AC3: Link Bukti Dukung
H4: TW1 | I4: TW2 | J4: TW3 | K4: TW4 | L4: TW1 | M4: TW2 | N4: TW3 | O4: TW4 | P4: TW1 | Q4: TW2 | R4: TW3 | S4: TW4 | T4: TW1 | U4: TW2 | V4: TW3 | W4: TW4
A5: ESELON I
A6: T1
B7: S1
C8: IKU 1
D9: Proksi 1.1
D10: Proksi 1.2
D11: Proksi 1.3
C12: IKU 2
D13: Proksi 2.1
D14: Proksi 2.2
D15: Proksi 2.3
A16: T2
B17: S2
C18: IKU 3
D19: Proksi 3.1
D20: Proksi 3.2
D21: Proksi 4.3
C22: IKU 4
D23: Proksi 5.1
D24: Proksi 5.2
D25: Proksi 2.3
O27: Capaian Proksi IKU 1 | P27: rata2 capaian proksi IKU 1
O28: Capaian Proksi IKU 2 | P28: rata2 capaian proksi IKU 2
O29: Capaian Proksi IKU 3 | P29: rata2 capaian proksi IKU 3
O30: Capaian Proksi IKU 4 | P30: rata2 capaian proksi IKU 4
O31: Capaian IKU 1
O32: Capaian IKU 2
O33: Capaian IKU 3
O34: Capaian IKU 4
O35: Capaian Sasaran 1 | P35: rata2 capaian IKU 12
O36: Capaian Sasaran 2 | P36: rata2 capaian IKU 34
O37: Capaian Tujuan 1
O38: Capaian Tujuan 2
A40: ESELON II
A41: T1
B42: S1
C43: IKU 1
...

Sheet FRA_view
A2: Indikator Kinerja/Uraian | E2: Jenis | F2: Target | G2: Satuan | H2: Alokasi Target | L2: Realisasi | P2: Capaian Kinerja | X2: Analisis Pencapaian Kinerja di Triwulan Berjalan
P3: Terhadap Target Triwulanan | T3: Terhadap Target Setahun | X3: Kendala | Y3: Solusi | Z3: RTL | AA3: PIC TL | AB3: Batas Waktu TL | AC3: Link Bukti Dukung
H4: TW1 | I4: TW2 | J4: TW3 | K4: TW4 | L4: TW1 | M4: TW2 | N4: TW3 | O4: TW4 | P4: TW1 | Q4: TW2 | R4: TW3 | S4: TW4 | T4: TW1 | U4: TW2 | V4: TW3 | W4: TW4
A5: ESELON I
A6: T1
B7: S1
C8: IKU 1 | E8: =FRA_input!E8 -> 0 | F8: =FRA_input!F8 -> 0 | G8: =FRA_input!G8 -> 0 | H8: =FRA_input!H8 -> 0 | I8: =FRA_input!I8 -> 0 | J8: =FRA_input!J8 -> 0 | K8: =FRA_input!K8 -> 0 | L8: =FRA_input!L8 -> 0 | ... AC8: =FRA_input!AC8 -> 0
D9: Proksi 1.1 | E9: =FRA_input!E9 -> 0 | F9: =FRA_input!F9 -> 0 | G9: =FRA_input!G9 -> 0 | H9: =FRA_input!H9 -> 0 | I9: =FRA_input!I9 -> 0 | J9: =FRA_input!J9 -> 0 | K9: =FRA_input!K9 -> 0 | L9: =FRA_input!L9 -> 0 | ... AC9: =FRA_input!AC9 -> 0
D10: Proksi 1.2 | E10: =FRA_input!E10 -> 0 | F10: =FRA_input!F10 -> 0 | G10: =FRA_input!G10 -> 0 | H10: =FRA_input!H10 -> 0 | I10: =FRA_input!I10 -> 0 | J10: =FRA_input!J10 -> 0 | K10: =FRA_input!K10 -> 0 | L10: =FRA_input!L10 -> 0 | ... AC10: =FRA_input!AC10 -> 0
D11: Proksi 1.3 | E11: =FRA_input!E11 -> 0 | F11: =FRA_input!F11 -> 0 | G11: =FRA_input!G11 -> 0 | H11: =FRA_input!H11 -> 0 | I11: =FRA_input!I11 -> 0 | J11: =FRA_input!J11 -> 0 | K11: =FRA_input!K11 -> 0 | L11: =FRA_input!L11 -> 0 | ... AC11: =FRA_input!AC11 -> 0
C12: IKU 2 | E12: =FRA_input!E12 -> 0 | F12: =FRA_input!F12 -> 0 | G12: =FRA_input!G12 -> 0 | H12: =FRA_input!H12 -> 0 | I12: =FRA_input!I12 -> 0 | J12: =FRA_input!J12 -> 0 | K12: =FRA_input!K12 -> 0 | L12: =FRA_input!L12 -> 0 | ... AC12: =FRA_input!AC12 -> 0
D13: Proksi 2.1 | E13: =FRA_input!E13 -> 0 | F13: =FRA_input!F13 -> 0 | G13: =FRA_input!G13 -> 0 | H13: =FRA_input!H13 -> 0 | I13: =FRA_input!I13 -> 0 | J13: =FRA_input!J13 -> 0 | K13: =FRA_input!K13 -> 0 | L13: =FRA_input!L13 -> 0 | ... AC13: =FRA_input!AC13 -> 0
D14: Proksi 2.2 | E14: =FRA_input!E14 -> 0 | F14: =FRA_input!F14 -> 0 | G14: =FRA_input!G14 -> 0 | H14: =FRA_input!H14 -> 0 | I14: =FRA_input!I14 -> 0 | J14: =FRA_input!J14 -> 0 | K14: =FRA_input!K14 -> 0 | L14: =FRA_input!L14 -> 0 | ... AC14: =FRA_input!AC14 -> 0
D15: Proksi 2.3 | E15: =FRA_input!E15 -> 0 | F15: =FRA_input!F15 -> 0 | G15: =FRA_input!G15 -> 0 | H15: =FRA_input!H15 -> 0 | I15: =FRA_input!I15 -> 0 | J15: =FRA_input!J15 -> 0 | K15: =FRA_input!K15 -> 0 | L15: =FRA_input!L15 -> 0 | ... AC15: =FRA_input!AC15 -> 0
A16: T2 | E16: =FRA_input!E16 -> 0 | F16: =FRA_input!F16 -> 0 | G16: =FRA_input!G16 -> 0 | H16: =FRA_input!H16 -> 0 | I16: =FRA_input!I16 -> 0 | J16: =FRA_input!J16 -> 0
B17: S2 | E17: =FRA_input!E17 -> 0 | F17: =FRA_input!F17 -> 0 | G17: =FRA_input!G17 -> 0 | H17: =FRA_input!H17 -> 0 | I17: =FRA_input!I17 -> 0 | J17: =FRA_input!J17 -> 0
C18: IKU 3 | E18: =FRA_input!E18 -> 0 | F18: =FRA_input!F18 -> 0 | G18: =FRA_input!G18 -> 0 | H18: =FRA_input!H18 -> 0 | I18: =FRA_input!I18 -> 0 | J18: =FRA_input!J18 -> 0 | K18: =FRA_input!K18 -> 0 | L18: =FRA_input!L18 -> 0 | ... AC18: =FRA_input!AC18 -> 0
D19: Proksi 3.1 | E19: =FRA_input!E19 -> 0 | F19: =FRA_input!F19 -> 0 | G19: =FRA_input!G19 -> 0 | H19: =FRA_input!H19 -> 0 | I19: =FRA_input!I19 -> 0 | J19: =FRA_input!J19 -> 0 | K19: =FRA_input!K19 -> 0 | L19: =FRA_input!L19 -> 0 | ... AC19: =FRA_input!AC19 -> 0
D20: Proksi 3.2 | E20: =FRA_input!E20 -> 0 | F20: =FRA_input!F20 -> 0 | G20: =FRA_input!G20 -> 0 | H20: =FRA_input!H20 -> 0 | I20: =FRA_input!I20 -> 0 | J20: =FRA_input!J20 -> 0 | K20: =FRA_input!K20 -> 0 | L20: =FRA_input!L20 -> 0 | ... AC20: =FRA_input!AC20 -> 0
D21: Proksi 4.3 | E21: =FRA_input!E21 -> 0 | F21: =FRA_input!F21 -> 0 | G21: =FRA_input!G21 -> 0 | H21: =FRA_input!H21 -> 0 | I21: =FRA_input!I21 -> 0 | J21: =FRA_input!J21 -> 0 | K21: =FRA_input!K21 -> 0 | L21: =FRA_input!L21 -> 0 | ... AC21: =FRA_input!AC21 -> 0
C22: IKU 4 | E22: =FRA_input!E22 -> 0 | F22: =FRA_input!F22 -> 0 | G22: =FRA_input!G22 -> 0 | H22: =FRA_input!H22 -> 0 | I22: =FRA_input!I22 -> 0 | J22: =FRA_input!J22 -> 0 | K22: =FRA_input!K22 -> 0 | L22: =FRA_input!L22 -> 0 | ... AC22: =FRA_input!AC22 -> 0
D23: Proksi 5.1 | E23: =FRA_input!E23 -> 0 | F23: =FRA_input!F23 -> 0 | G23: =FRA_input!G23 -> 0 | H23: =FRA_input!H23 -> 0 | I23: =FRA_input!I23 -> 0 | J23: =FRA_input!J23 -> 0 | K23: =FRA_input!K23 -> 0 | L23: =FRA_input!L23 -> 0 | ... AC23: =FRA_input!AC23 -> 0
D24: Proksi 5.2 | E24: =FRA_input!E24 -> 0 | F24: =FRA_input!F24 -> 0 | G24: =FRA_input!G24 -> 0 | H24: =FRA_input!H24 -> 0 | I24: =FRA_input!I24 -> 0 | J24: =FRA_input!J24 -> 0 | K24: =FRA_input!K24 -> 0 | L24: =FRA_input!L24 -> 0 | ... AC24: =FRA_input!AC24 -> 0
D25: Proksi 2.3 | E25: =FRA_input!E25 -> 0 | F25: =FRA_input!F25 -> 0 | G25: =FRA_input!G25 -> 0 | H25: =FRA_input!H25 -> 0 | I25: =FRA_input!I25 -> 0 | J25: =FRA_input!J25 -> 0 | K25: =FRA_input!K25 -> 0 | L25: =FRA_input!L25 -> 0 | ... AC25: =FRA_input!AC25 -> 0
D27: REPORT CAPAIAN KINERJA | O27: Capaian Proksi IKU 1 | P27: rata2 capaian proksi IKU 1
O28: Capaian Proksi IKU 2 | P28: rata2 capaian proksi IKU 2
O29: Capaian Proksi IKU 3 | P29: rata2 capaian proksi IKU 3
O30: Capaian Proksi IKU 4 | P30: rata2 capaian proksi IKU 4
O31: Capaian IKU 1
O32: Capaian IKU 2
O33: Capaian IKU 3
O34: Capaian IKU 4
O35: Capaian Sasaran 1 | P35: rata2 capaian IKU 12
O36: Capaian Sasaran 2 | P36: rata2 capaian IKU 34
O37: Capaian Tujuan 1
O38: Capaian Tujuan 2
A40: ESELON II
A41: T1
B42: S1
C43: IKU 1 | E43: =FRA_input!E43 -> 0 | F43: =FRA_input!F43 -> 0 | G43: =FRA_input!G43 -> 0 | H43: =FRA_input!H43 -> 0 | I43: =FRA_input!I43 -> 0 | J43: =FRA_input!J43 -> 0 | K43: =FRA_input!K43 -> 0 | L43: =FRA_input!L43 -> 0 | ... AC43: =FRA_input!AC43 -> 0
...
